<robot name = "robot">
    <link name="Head">
        <inertial>
            <origin xyz="0 0 0.5" rpy="0 0 0"/>
            <mass value="1" />
            <inertia ixx="100" ixy="0" ixz="0" iyy="100" iyz="0" izz="100" />
        </inertial>
        <visual>
            <origin xyz="0 0 0.5" rpy="0 0 0"/>
            <geometry>
                <box size="1 1 1" />
            </geometry>
            <material name="Cyan">
                <color rgba="0 1.0 1.0 1.0"/>
            </material>
        </visual>
        <collision>
            <origin xyz="0 0 0.5" rpy="0 0 0"/>
            <geometry>
                <box size="1 1 1" />
            </geometry>
        </collision>
    </link>
    <joint name="Head_Seg-0" type="revolute">
       <parent link="Head"/>
       <child  link="Seg-0"/>
       <origin rpy="0 0 0" xyz="0.5 0.5 0" />
     <axis xyz="1 0 0"/>
       <limit effort="0.0" lower="-3.14159" upper="3.14159" velocity="0.0"/>
    </joint>
    <link name="Seg-0">
        <inertial>
            <origin xyz="0.08108714751845547 0.18798848970950077 0.13808252750424937" rpy="0 0 0"/>
            <mass value="1" />
            <inertia ixx="100" ixy="0" ixz="0" iyy="100" iyz="0" izz="100" />
        </inertial>
        <visual>
            <origin xyz="0.08108714751845547 0.18798848970950077 0.13808252750424937" rpy="0 0 0"/>
            <geometry>
                <box size="0.16217429503691094 0.37597697941900154 0.27616505500849875" />
            </geometry>
            <material name="Cyan">
                <color rgba="0 1.0 1.0 1.0"/>
            </material>
        </visual>
        <collision>
            <origin xyz="0.08108714751845547 0.18798848970950077 0.13808252750424937" rpy="0 0 0"/>
            <geometry>
                <box size="0.16217429503691094 0.37597697941900154 0.27616505500849875" />
            </geometry>
        </collision>
    </link>
    <joint name="Seg-0_Seg-1" type="revolute">
       <parent link="Seg-0"/>
       <child  link="Seg-1"/>
       <origin rpy="0 0 0" xyz="0.08108714751845547 0.0 0.0" />
     <axis xyz="0 0 1"/>
       <limit effort="0.0" lower="-3.14159" upper="3.14159" velocity="0.0"/>
    </joint>
    <link name="Seg-1">
        <inertial>
            <origin xyz="0.21081020428835406 0.3385400944226855 0.4302259549110805" rpy="0 0 0"/>
            <mass value="1" />
            <inertia ixx="100" ixy="0" ixz="0" iyy="100" iyz="0" izz="100" />
        </inertial>
        <visual>
            <origin xyz="0.21081020428835406 0.3385400944226855 0.4302259549110805" rpy="0 0 0"/>
            <geometry>
                <box size="0.42162040857670813 0.677080188845371 0.860451909822161" />
            </geometry>
            <material name="Cyan">
                <color rgba="0 1.0 1.0 1.0"/>
            </material>
        </visual>
        <collision>
            <origin xyz="0.21081020428835406 0.3385400944226855 0.4302259549110805" rpy="0 0 0"/>
            <geometry>
                <box size="0.42162040857670813 0.677080188845371 0.860451909822161" />
            </geometry>
        </collision>
    </link>
    <joint name="Seg-1_Seg-2" type="revolute">
       <parent link="Seg-1"/>
       <child  link="Seg-2"/>
       <origin rpy="0 0 0" xyz="0.21081020428835406 0.3385400944226855 0.860451909822161" />
     <axis xyz="0 1 0"/>
       <limit effort="0.0" lower="-3.14159" upper="3.14159" velocity="0.0"/>
    </joint>
    <link name="Seg-2">
        <inertial>
            <origin xyz="0.4628400734802796 0.29465433024891374 0.028960982398801238" rpy="0 0 0"/>
            <mass value="1" />
            <inertia ixx="100" ixy="0" ixz="0" iyy="100" iyz="0" izz="100" />
        </inertial>
        <visual>
            <origin xyz="0.4628400734802796 0.29465433024891374 0.028960982398801238" rpy="0 0 0"/>
            <geometry>
                <box size="0.9256801469605592 0.5893086604978275 0.057921964797602477" />
            </geometry>
            <material name="Cyan">
                <color rgba="0 1.0 1.0 1.0"/>
            </material>
        </visual>
        <collision>
            <origin xyz="0.4628400734802796 0.29465433024891374 0.028960982398801238" rpy="0 0 0"/>
            <geometry>
                <box size="0.9256801469605592 0.5893086604978275 0.057921964797602477" />
            </geometry>
        </collision>
    </link>
    <joint name="Seg-2_Seg-3" type="revolute">
       <parent link="Seg-2"/>
       <child  link="Seg-3"/>
       <origin rpy="0 0 0" xyz="0.4628400734802796 0.29465433024891374 0.057921964797602477" />
     <axis xyz="1 0 0"/>
       <limit effort="0.0" lower="-3.14159" upper="3.14159" velocity="0.0"/>
    </joint>
    <link name="Seg-3">
        <inertial>
            <origin xyz="0.47592947131824087 0.20841400069254146 0.17835584059132903" rpy="0 0 0"/>
            <mass value="1" />
            <inertia ixx="100" ixy="0" ixz="0" iyy="100" iyz="0" izz="100" />
        </inertial>
        <visual>
            <origin xyz="0.47592947131824087 0.20841400069254146 0.17835584059132903" rpy="0 0 0"/>
            <geometry>
                <box size="0.9518589426364817 0.4168280013850829 0.35671168118265806" />
            </geometry>
            <material name="Cyan">
                <color rgba="0 1.0 1.0 1.0"/>
            </material>
        </visual>
        <collision>
            <origin xyz="0.47592947131824087 0.20841400069254146 0.17835584059132903" rpy="0 0 0"/>
            <geometry>
                <box size="0.9518589426364817 0.4168280013850829 0.35671168118265806" />
            </geometry>
        </collision>
    </link>
    <joint name="Seg-3_Seg-4" type="revolute">
       <parent link="Seg-3"/>
       <child  link="Seg-4"/>
       <origin rpy="0 0 0" xyz="0.47592947131824087 0.20841400069254146 0.35671168118265806" />
     <axis xyz="0 0 1"/>
       <limit effort="0.0" lower="-3.14159" upper="3.14159" velocity="0.0"/>
    </joint>
    <link name="Seg-4">
        <inertial>
            <origin xyz="0.2377578090707601 0.3941892752859682 0.3248793710486364" rpy="0 0 0"/>
            <mass value="1" />
            <inertia ixx="100" ixy="0" ixz="0" iyy="100" iyz="0" izz="100" />
        </inertial>
        <visual>
            <origin xyz="0.2377578090707601 0.3941892752859682 0.3248793710486364" rpy="0 0 0"/>
            <geometry>
                <box size="0.4755156181415202 0.7883785505719364 0.6497587420972728" />
            </geometry>
            <material name="Cyan">
                <color rgba="0 1.0 1.0 1.0"/>
            </material>
        </visual>
        <collision>
            <origin xyz="0.2377578090707601 0.3941892752859682 0.3248793710486364" rpy="0 0 0"/>
            <geometry>
                <box size="0.4755156181415202 0.7883785505719364 0.6497587420972728" />
            </geometry>
        </collision>
    </link>
    <joint name="Seg-4_Seg-5" type="revolute">
       <parent link="Seg-4"/>
       <child  link="Seg-5"/>
       <origin rpy="0 0 0" xyz="0.0 0.3941892752859682 0.6497587420972728" />
     <axis xyz="0 1 0"/>
       <limit effort="0.0" lower="-3.14159" upper="3.14159" velocity="0.0"/>
    </joint>
    <link name="Seg-5">
        <inertial>
            <origin xyz="0.10771878795295425 0.1493570174026091 0.49396851439462286" rpy="0 0 0"/>
            <mass value="1" />
            <inertia ixx="100" ixy="0" ixz="0" iyy="100" iyz="0" izz="100" />
        </inertial>
        <visual>
            <origin xyz="0.10771878795295425 0.1493570174026091 0.49396851439462286" rpy="0 0 0"/>
            <geometry>
                <box size="0.2154375759059085 0.2987140348052182 0.9879370287892457" />
            </geometry>
            <material name="Cyan">
                <color rgba="0 1.0 1.0 1.0"/>
            </material>
        </visual>
        <collision>
            <origin xyz="0.10771878795295425 0.1493570174026091 0.49396851439462286" rpy="0 0 0"/>
            <geometry>
                <box size="0.2154375759059085 0.2987140348052182 0.9879370287892457" />
            </geometry>
        </collision>
    </link>
    <joint name="Seg-5_Seg-6" type="revolute">
       <parent link="Seg-5"/>
       <child  link="Seg-6"/>
       <origin rpy="0 0 0" xyz="0.10771878795295425 0.0 0.0" />
     <axis xyz="0 0 1"/>
       <limit effort="0.0" lower="-3.14159" upper="3.14159" velocity="0.0"/>
    </joint>
    <link name="Seg-6">
        <inertial>
            <origin xyz="0.24192030243798668 0.16153642385321054 0.12068498490257645" rpy="0 0 0"/>
            <mass value="1" />
            <inertia ixx="100" ixy="0" ixz="0" iyy="100" iyz="0" izz="100" />
        </inertial>
        <visual>
            <origin xyz="0.24192030243798668 0.16153642385321054 0.12068498490257645" rpy="0 0 0"/>
            <geometry>
                <box size="0.48384060487597336 0.3230728477064211 0.2413699698051529" />
            </geometry>
            <material name="Cyan">
                <color rgba="0 1.0 1.0 1.0"/>
            </material>
        </visual>
        <collision>
            <origin xyz="0.24192030243798668 0.16153642385321054 0.12068498490257645" rpy="0 0 0"/>
            <geometry>
                <box size="0.48384060487597336 0.3230728477064211 0.2413699698051529" />
            </geometry>
        </collision>
    </link>
</robot>